Workbook

Sheet Kirish
A1: BioPlast Tech — asosiy farazlar (ko'k = kiritiladigan qiymat, sariq = asosiy faraz)
A2: Narxlar AQSh dollarida, QQSsiz, real (inflyatsiyasiz) ifodada. Ko'k raqamlarni o'zgartirsangiz, barcha varaqlar avtomatik qayta hisoblanadi.
A3: Ko'rsatkich | B3: Qiymat | C3: Birlik | D3: Manba / izoh
A4: Makroiqtisodiy
A5: Valyuta kursi | B5: 12000 | C5: so'm / $ | D5: O'zR MB: 22.10.2026 da 11 966 so'm; yaxlitlangan. cbu.uz
A6: Elektr energiya tarifi (yuridik shaxslar) | B6: 1100 | C6: so'm / kWh | D6: VM qarori, 01.06.2026 dan (kun.uz, 15.05.2026; interfax.com)
A7: Tabiiy gaz tarifi (yuridik shaxslar) | B7: 2000 | C7: so'm / m³ | D7: 01.06.2026 dan (interfax.com, 15.05.2026)
A8: Foyda solig'i | B8: 0.15 | C8: % | D8: O'zR Soliq kodeksi, 337-modda — 15%
A9: Ijtimoiy soliq | B9: 0.12 | C9: % | D9: O'zR Soliq kodeksi — 12% (ish haqi fondiga)
A10: Diskont stavkasi (USD, xavf bilan) | B10: 0.15 | C10: % | D10: Startap xavfi hisobga olingan faraz
A11: PHA ishlab chiqarish (Cupriavidus necator H16)
A12: PHA chiqishi (substrat bo'yicha) | B12: 0.55 | C12: kg PHA / kg yog' | D12: Nazariy maks. ~0.7; o'simlik yog'ida 0.6–0.8 qayd etilgan, konservativ
A13: Xomashyo: ishlatilgan yog' / soapstok narxi | B13: 500 | C13: $ / t | D13: Faraz: yog'-moy kombinatlari va HoReCa'dan kelishuv narxi — KP bilan tasdiqlash kerak
A14: Ozuqa tuzlari (N, P, mikroelementlar) | B14: 120 | C14: $ / t PHA | D14: Faraz (ammoniy sulfat, KH2PO4, MgSO4, iz elementlar)
A15: Ajratish kimyoviy moddalari (NaOH, SDS/NaClO) | B15: 300 | C15: $ / t PHA | D15: Faraz; erituvchisiz ajratish usuli
A16: Elektr sarfi | B16: 9000 | C16: kWh / t PHA | D16: Aeratsiya, aralashtirish, separator, quritish — kichik masshtab
A17: Gaz sarfi (bug' qozoni) | B17: 1900 | C17: m³ / t PHA | D17: ~25 t bug' / t PHA, 75 m³ gaz / t bug'
A18: Suv va oqova suv | B18: 60 | C18: $ / t PHA | D18: Faraz
A19: Qadoqlash (25 kg qop) | B19: 30 | C19: $ / t PHA | D19: Faraz
A20: Kompost bo'ladigan plyonka / paket (PBAT + PLA + PHA)
A21: PBAT narxi (O'zbekistonga yetkazilgan) | B21: 1700 | C21: $ / t | D21: Xitoy: 9 850 yuan/t (CICC, 21.09.2025) + logistika va bojxona
A22: PLA narxi (yetkazilgan) | B22: 2600 | C22: $ / t | D22: Xitoy: 2 010–2 520 $/t (Intratec, 2025) + logistika
A23: Qo'shimchalar (CaCO3, kompatibilizator, masterbatch) | B23: 900 | C23: $ / t | D23: Faraz
A24: Qo'shimchalar ulushi | B24: 0.08 | C24: % | D24: Retsept
A25: PBAT : (PBAT+PLA) nisbati | B25: 0.72 | C25: % | D25: Retsept — qolgani PLA
A26: Ishlab chiqarish chiqindisi (yo'qotish) | B26: 0.05 | C26: % | D26: Qisman qayta ishlatiladi
A27: Elektr sarfi (kompaund + plyonka + paket) | B27: 900 | C27: kWh / t | D27: Faraz
A28: Qadoqlash, bo'yoq | B28: 110 | C28: $ / t | D28: Faraz
A29: Sotish narxlari (QQSsiz, zavoddan)
A30: Kompost bo'ladigan paket/plyonka narxi | B30: 3900 | C30: $ / t | D30: Polietilen paketdan ~2 baravar qimmat; import analoglaridan arzon
A31: Toza PHA granula narxi | B31: 4500 | C31: $ / t | D31: IMARC: 3 443–3 712 $/t (12.2025); Mordor: 4 000–15 000 $/t
A32: Sotish va logistika xarajati | B32: 0.04 | C32: % daromaddan | D32: Faraz
A33: Doimiy xarajatlar
A34: Ishlab chiqarish maydoni | B34: 1500 | C34: m² | D34: Toshkent viloyati sanoat zonasi
A35: Ijara narxi | B35: 4 | C35: $ / m² / oy | D35: Faraz — mahalliy taklif bilan tasdiqlash
A36: Ta'mirlash va ehtiyot qismlar | B36: 0.03 | C36: % uskuna qiymatidan / yil | D36: Faraz
A37: Marketing (doimiy qism) | B37: 30000 | C37: $ / yil | D37: Ko'rgazmalar, sertifikat markirovkasi, raqamli marketing
A38: Ma'muriy, sug'urta, IT | B38: 20000 | C38: $ / yil | D38: Faraz
A39: Sertifikatni yangilash, laboratoriya sinovlari | B39: 10000 | C39: $ / yil | D39: TÜV AUSTRIA / DIN CERTCO audit
A40: Ilmiy-tadqiqot (shtamm, retsept) | B40: 25000 | C40: $ / yil | D40: TKTI bilan hamkorlik
...

Sheet CAPEX
A1: Kapital xarajatlar (CAPEX) — uskunalar va yetkazib beruvchilar
A2: Narxlar — 2025–2026 yillardagi ochiq bozor e'lonlari va ishlab chiqaruvchi narx diapazonlari asosidagi taxmin. Sotib olishdan oldin kamida 3 ta tijorat taklifi (KP) olinishi shart.
A3: № | B3: Uskuna / xarajat | C3: Faza | D3: Turi (U=uskuna, B=boshqa) | E3: Soni | F3: Narx ($) | G3: Jami ($) | H3: Yetkazib beruvchilar (misol)
A4: 1 | B4: Stol usti bioreaktor 5 L (pH, DO, harorat nazorati) | C4: 1 | D4: U | E4: 2 | F4: 12000 | G4: =E4*F4 -> 24000 | H4: Sartorius BIOSTAT A; Eppendorf BioFlo 120; Bailun BLBIO-5GJ
A5: 2 | B5: Avtoklav 75 L | C5: 1 | D5: U | E5: 1 | F5: 7000 | G5: =E5*F5 -> 7000 | H5: Tuttnauer; Systec; Xitoy: Zealway
A6: 3 | B6: Chayqatuvchi inkubator (shaker) | C6: 1 | D6: U | E6: 1 | F6: 6000 | G6: =E6*F6 -> 6000 | H6: Eppendorf Innova; Infors HT; Zhicheng
A7: 4 | B7: Laminar boks (II klass) | C7: 1 | D7: U | E7: 1 | F7: 5000 | G7: =E7*F7 -> 5000 | H7: Esco; Thermo Fisher; Biobase
A8: 5 | B8: Laboratoriya sentrifugasi | C8: 1 | D8: U | E8: 1 | F8: 5000 | G8: =E8*F8 -> 5000 | H8: Eppendorf; Hettich; Hunan Xiangyi
A9: 6 | B9: Mikroskop (fazali kontrast) | C9: 1 | D9: U | E9: 1 | F9: 2500 | G9: =E9*F9 -> 2500 | H9: Olympus/Evident; Zeiss; Optika
A10: 7 | B10: Spektrofotometr UV-Vis (OD600) | C10: 1 | D10: U | E10: 1 | F10: 4000 | G10: =E10*F10 -> 4000 | H10: Shimadzu; Thermo; Biobase
A11: 8 | B11: Gaz xromatograf GC-FID (PHA miqdori) | C11: 1 | D11: U | E11: 1 | F11: 35000 | G11: =E11*F11 -> 35000 | H11: Agilent 8860; Shimadzu GC-2030; Fuli
A12: 9 | B12: Quritish shkafi, analitik tarozi, pH-metr | C12: 1 | D12: U | E12: 1 | F12: 5000 | G12: =E12*F12 -> 5000 | H12: Memmert; Ohaus; Mettler Toledo
A13: 10 | B13: Erish oqimi indeksi (MFI) asbobi | C13: 1 | D13: U | E13: 1 | F13: 4000 | G13: =E13*F13 -> 4000 | H13: Instron/CEAST; Xitoy: Chengde
A14: 11 | B14: Universal cho'zilish sinov mashinasi | C14: 1 | D14: U | E14: 1 | F14: 12000 | G14: =E14*F14 -> 12000 | H14: Instron; Zwick; WANCE
A15: 12 | B15: Pilot fermenter 300 L + urug' 30 L | C15: 1 | D15: U | E15: 1 | F15: 45000 | G15: =E15*F15 -> 45000 | H15: Bailun (BLBIO); T&J Bio-engineering; Zhengzhou Laboao
... A39: 36 | B39: PLC/SCADA avtomatlashtirish | C39: 2 | D39: U | E39: 1 | F39: 25000 | G39: =E39*F39 -> 25000 | H39: Siemens; Schneider Electric; Delta
B41: Jamlanma | F41: 1-faza ($) | G41: 2-faza ($) | H41: Jami ($)
B42: Uskunalar | F42: =SUMIFS($G$4:$G$39,$C$4:$C$39,1,$D$4:$D$39,"U") -> 409500 | G42: =SUMIFS($G$4:$G$39,$C$4:$C$39,2,$D$4:$D$39,"U") -> 700000 | H42: =F42+G42 -> 1109500
B43: Yetkazish, bojxona rasmiylashtiruvi | F43: =F42*$F$50 -> 49140 | G43: =G42*$F$50 -> 84000 | H43: =F43+G43 -> 133140
B44: Montaj, quvurlar, elektr ulanish | F44: =F42*$F$51 -> 61425 | G44: =G42*$F$51 -> 105000 | H44: =F44+G44 -> 166425
B45: Boshqa (bino, sertifikat, loyihalash) | F45: =SUMIFS($G$4:$G$39,$C$4:$C$39,1,$D$4:$D$39,"B") -> 140000 | G45: =SUMIFS($G$4:$G$39,$C$4:$C$39,2,$D$4:$D$39,"B") -> 0 | H45: =F45+G45 -> 140000
B46: Oraliq jami | F46: =SUM(F42:F45) -> 660065 | G46: =SUM(G42:G45) -> 889000 | H46: =F46+G46 -> 1549065
B47: Kutilmagan xarajatlar | F47: =F46*$F$52 -> 66006.5 | G47: =G46*$F$52 -> 88900 | H47: =F47+G47 -> 154906.5
B48: JAMI CAPEX | F48: =F46+F47 -> 726071.5 | G48: =G46+G47 -> 977900 | H48: =F48+G48 -> 1703971.5
B50: Yetkazish va bojxona stavkasi (uskunadan) | F50: 0.12 | H50: Texnologik uskunalar uchun boj imtiyozlari bo'lishi mumkin — konservativ hisob
B51: Montaj stavkasi (uskunadan) | F51: 0.15
B52: Kutilmagan xarajatlar stavkasi | F52: 0.1

Sheet Xodimlar
A1: Xodimlar va ish haqi fondi
A3: Lavozim | B3: 1-yil soni | C3: 2-yildan soni | D3: Oylik ish haqi ($, brutto) | E3: 1-yil fondi ($) | F3: 2-yildan fondi ($) | G3: Izoh
A4: Direktor | B4: 1 | C4: 1 | D4: 1500 | E4: =B4*D4*12 -> 18000 | F4: =C4*D4*12 -> 18000
A5: Bosh texnolog-mikrobiolog | B5: 1 | C5: 1 | D5: 1200 | E5: =B5*D5*12 -> 14400 | F5: =C5*D5*12 -> 14400 | G5: Biotexnologiya magistri; TKTI bitiruvchisi
A6: Mikrobiolog / laborant | B6: 2 | C6: 3 | D6: 700 | E6: =B6*D6*12 -> 16800 | F6: =C6*D6*12 -> 25200 | G6: Shtamm saqlash, sifat tahlili, GC
A7: Fermentatsiya va ajratish operatori | B7: 2 | C7: 8 | D7: 550 | E7: =B7*D7*12 -> 13200 | F7: =C7*D7*12 -> 52800 | G7: 24/7, 4 smena × 2 kishi
A8: Ekstruziya va plyonka operatori | B8: 6 | C8: 9 | D8: 550 | E8: =B8*D8*12 -> 39600 | F8: =C8*D8*12 -> 59400 | G8: 3 smena
A9: Paket kesish va qadoqlash ishchisi | B9: 3 | C9: 6 | D9: 450 | E9: =B9*D9*12 -> 16200 | F9: =C9*D9*12 -> 32400
A10: Mexanik-elektrik (KIP) | B10: 1 | C10: 2 | D10: 600 | E10: =B10*D10*12 -> 7200 | F10: =C10*D10*12 -> 14400
A11: Sifat nazorati muhandisi | B11: 1 | C11: 1 | D11: 650 | E11: =B11*D11*12 -> 7800 | F11: =C11*D11*12 -> 7800 | G11: ISO 9001 tizimi
A12: Savdo va marketing menejeri | B12: 1 | C12: 2 | D12: 700 | E12: =B12*D12*12 -> 8400 | F12: =C12*D12*12 -> 16800 | G12: B2B savdo, eksport
A13: Bosh hisobchi | B13: 1 | C13: 1 | D13: 700 | E13: =B13*D13*12 -> 8400 | F13: =C13*D13*12 -> 8400
A14: Omborchi-logist | B14: 1 | C14: 1 | D14: 450 | E14: =B14*D14*12 -> 5400 | F14: =C14*D14*12 -> 5400
A15: Jami | B15: =SUM(B4:B14) -> 20 | C15: =SUM(C4:C14) -> 35 | E15: =SUM(E4:E14) -> 155400 | F15: =SUM(F4:F14) -> 255000
A16: Ijtimoiy soliq bilan jami fond | E16: =E15*(1+Kirish!$B$9) -> 174048 | F16: =F15*(1+Kirish!$B$9) -> 285600
A18: Ma'lumot uchun: O'zbekistonda o'rtacha oylik ish haqi 2026-yil I chorakda 6,8 mln so'm (~$570) — stat.uz / kun.uz.

Sheet Tannarx
A1: 1 tonna mahsulotning o'zgaruvchan tannarxi
A3: Xarajat moddasi | B3: Hisob | C3: $ / t | D3: Ulush
A4: A) Toza PHA granula (1 t)
A5: Yog' xomashyosi | B5: 1/chiqish × narx | C5: =1/Kirish!$B$12*Kirish!$B$13 -> 909.09091 | D5: =C5/$C$12 -> 0.35500858
A6: Ozuqa tuzlari | C6: =Kirish!$B$14 -> 120 | D6: =C6/$C$12 -> 0.046861132
A7: Ajratish kimyoviy moddalari | C7: =Kirish!$B$15 -> 300 | D7: =C7/$C$12 -> 0.11715283
A8: Elektr energiya | B8: kWh × tarif | C8: =Kirish!$B$16*Kirish!$B$49 -> 825 | D8: =C8/$C$12 -> 0.32217029
A9: Tabiiy gaz (bug') | B9: m³ × tarif | C9: =Kirish!$B$17*Kirish!$B$50 -> 316.66667 | D9: =C9/$C$12 -> 0.12366132
A10: Suv va oqova | C10: =Kirish!$B$18 -> 60 | D10: =C10/$C$12 -> 0.023430566
A11: Qadoqlash | C11: =Kirish!$B$19 -> 30 | D11: =C11/$C$12 -> 0.011715283
A12: PHA o'zgaruvchan tannarxi | C12: =SUM(C5:C11) -> 2560.7576
A14: B) Kompost bo'ladigan paket/plyonka (1 t, PHA ulushi 6,5% bo'lganda)
A15: Namuna retseptdagi PHA ulushi | C15: 0.065
A16: PBAT | B16: ulush × narx × (1+yo'qotish) | C16: =(1-$C$15-Kirish!$B$24)*Kirish!$B$25*Kirish!$B$21*(1+Kirish!$B$26) -> 1098.846 | D16: =C16/$C$22 -> 0.50054943
A17: PLA | C17: =(1-$C$15-Kirish!$B$24)*(1-Kirish!$B$25)*Kirish!$B$22*(1+Kirish!$B$26) -> 653.562 | D17: =C17/$C$22 -> 0.2977124
A18: Qo'shimchalar | C18: =Kirish!$B$24*Kirish!$B$23*(1+Kirish!$B$26) -> 75.6 | D18: =C18/$C$22 -> 0.034437525
A19: PHA (ichki tannarxda) | C19: =$C$15*Tannarx!$C$12*(1+Kirish!$B$26) -> 174.7717 | D19: =C19/$C$22 -> 0.0796125
A20: Elektr energiya | C20: =Kirish!$B$27*Kirish!$B$49 -> 82.5 | D20: =C20/$C$22 -> 0.037580633
A21: Qadoqlash, bo'yoq | C21: =Kirish!$B$28 -> 110 | D21: =C21/$C$22 -> 0.05010751
A22: Paket/plyonka o'zgaruvchan tannarxi | C22: =SUM(C16:C21) -> 2195.2797
A23: Sotish narxi | C23: =Kirish!$B$30 -> 3900
A24: Marjinal foyda (sotish xarajatidan oldin) | C24: =C23-C22 -> 1704.7203 | D24: =C24/C23 -> 0.43710777

Sheet Prognoz
A1: Daromad, xarajat, foyda va pul oqimi prognozi ($)
A3: Ko'rsatkich | B3: 2027 (0-yil) | C3: 2028 (1-yil) | D3: 2029 (2-yil) | E3: 2030 (3-yil) | F3: 2031 (4-yil) | G3: 2032 (5-yil) | H3: 2033 (6-yil) | I3: 2034 (7-yil) | J3: Izoh
A4: Ishlab chiqarish hajmi
A5: Paket/plyonka ishlab chiqarish (t) | B5: 0 | C5: 300 | D5: 600 | E5: 800 | F5: 850 | G5: 850 | H5: 850 | I5: 850 | J5: 2 ta liniya × 90 kg/soat × 6 000 soat = 1 080 t maks. quvvat; barqaror yilda 79% yuklanish
A6: PHA ishlab chiqarish (t) | B6: 0 | C6: 3 | D6: 25 | E6: 55 | F6: 58 | G6: 58 | H6: 58 | I6: 58 | J6: 2027–28: 300 L pilot; 2029 o'rtasidan 2×10 m³ (≈160 partiya/yil × 0,36 t)
A7: PHA ulushi aralashmada | B7: 0 | C7: 0.01 | D7: 0.04 | E7: 0.065 | F7: 0.065 | G7: 0.065 | H7: 0.065 | I7: 0.065 | J7: Standart paketda 6,5% PHA; premium (uyda kompost) liniyada ulush yuqori
A8: PHA ichki ishlatish (t) | B8: =B5*B7 -> 0 | C8: =C5*C7 -> 3 | D8: =D5*D7 -> 24 | E8: =E5*E7 -> 52 | F8: =F5*F7 -> 55.25 | G8: =G5*G7 -> 55.25 | H8: =H5*H7 -> 55.25 | I8: =I5*I7 -> 55.25
A9: PHA sotish (t) | B9: =MAX(0,B6-B8) -> 0 | C9: =MAX(0,C6-C8) -> 0 | D9: =MAX(0,D6-D8) -> 1 | E9: =MAX(0,E6-E8) -> 3 | F9: =MAX(0,F6-F8) -> 2.75 | G9: =MAX(0,G6-G8) -> 2.75 | H9: =MAX(0,H6-H8) -> 2.75 | I9: =MAX(0,I6-I8) -> 2.75 | J9: Ichki ehtiyojdan ortiqcha qism sotiladi
A10: PHA yetishmovchiligi — sotib olinadi (t) | B10: =MAX(0,B8-B6) -> 0 | C10: =MAX(0,C8-C6) -> 0 | D10: =MAX(0,D8-D6) -> 0 | E10: =MAX(0,E8-E6) -> 0 | F10: =MAX(0,F8-F6) -> 0 | G10: =MAX(0,G8-G6) -> 0 | H10: =MAX(0,H8-H6) -> 0 | I10: =MAX(0,I8-I6) -> 0
A11: Daromad
A12: Paket/plyonka sotuvi | B12: =B5*Kirish!$B$30 -> 0 | C12: =C5*Kirish!$B$30 -> 1170000 | D12: =D5*Kirish!$B$30 -> 2340000 | E12: =E5*Kirish!$B$30 -> 3120000 | F12: =F5*Kirish!$B$30 -> 3315000 | G12: =G5*Kirish!$B$30 -> 3315000 | H12: =H5*Kirish!$B$30 -> 3315000 | I12: =I5*Kirish!$B$30 -> 3315000
A13: Toza PHA sotuvi | B13: =B9*Kirish!$B$31 -> 0 | C13: =C9*Kirish!$B$31 -> 0 | D13: =D9*Kirish!$B$31 -> 4500 | E13: =E9*Kirish!$B$31 -> 13500 | F13: =F9*Kirish!$B$31 -> 12375 | G13: =G9*Kirish!$B$31 -> 12375 | H13: =H9*Kirish!$B$31 -> 12375 | I13: =I9*Kirish!$B$31 -> 12375
A14: JAMI DAROMAD | B14: =B12+B13 -> 0 | C14: =C12+C13 -> 1170000 | D14: =D12+D13 -> 2344500 | E14: =E12+E13 -> 3133500 | F14: =F12+F13 -> 3327375 | G14: =G12+G13 -> 3327375 | H14: =H12+H13 -> 3327375 | I14: =I12+I13 -> 3327375
A15: O'zgaruvchan xarajatlar
A16: Plyonka xomashyosi va energiya (PHA'siz) | B16: =B5*(((1-B7-Kirish!$B$24)*(Kirish!$B$25*Kirish!$B$21+(1-Kirish!$B$25)*Kirish!$B$22)+Kirish!$B$24*Kirish!$B$23)*(1+Kirish!$B$26)+Kirish!$B$27*Kirish!$B$49+Kirish!$B$28) -> 0 | C16: =C5*(((1-C7-Kirish!$B$24)*(Kirish!$B$25*Kirish!$B$21+(1-Kirish!$B$25)*Kirish!$B$22)+Kirish!$B$24*Kirish!$B$23)*(1+Kirish!$B$26)+Kirish!$B$27*Kirish!$B$49+Kirish!$B$28) -> 639970.8 | D16: =D5*(((1-D7-Kirish!$B$24)*(Kirish!$B$25*Kirish!$B$21+(1-Kirish!$B$25)*Kirish!$B$22)+Kirish!$B$24*Kirish!$B$23)*(1+Kirish!$B$26)+Kirish!$B$27*Kirish!$B$49+Kirish!$B$28) -> 1243048.8 | E16: =E5*(((1-E7-Kirish!$B$24)*(Kirish!$B$25*Kirish!$B$21+(1-Kirish!$B$25)*Kirish!$B$22)+Kirish!$B$24*Kirish!$B$23)*(1+Kirish!$B$26)+Kirish!$B$27*Kirish!$B$49+Kirish!$B$28) -> 1616406.4 | F16: =F5*(((1-F7-Kirish!$B$24)*(Kirish!$B$25*Kirish!$B$21+(1-Kirish!$B$25)*Kirish!$B$22)+Kirish!$B$24*Kirish!$B$23)*(1+Kirish!$B$26)+Kirish!$B$27*Kirish!$B$49+Kirish!$B$28) -> 1717431.8 | G16: =G5*(((1-G7-Kirish!$B$24)*(Kirish!$B$25*Kirish!$B$21+(1-Kirish!$B$25)*Kirish!$B$22)+Kirish!$B$24*Kirish!$B$23)*(1+Kirish!$B$26)+Kirish!$B$27*Kirish!$B$49+Kirish!$B$28) -> 1717431.8 | H16: =H5*(((1-H7-Kirish!$B$24)*(Kirish!$B$25*Kirish!$B$21+(1-Kirish!$B$25)*Kirish!$B$22)+Kirish!$B$24*Kirish!$B$23)*(1+Kirish!$B$26)+Kirish!$B$27*Kirish!$B$49+Kirish!$B$28) -> 1717431.8 | I16: =I5*(((1-I7-Kirish!$B$24)*(Kirish!$B$25*Kirish!$B$21+(1-Kirish!$B$25)*Kirish!$B$22)+Kirish!$B$24*Kirish!$B$23)*(1+Kirish!$B$26)+Kirish!$B$27*Kirish!$B$49+Kirish!$B$28) -> 1717431.8
A17: PHA ishlab chiqarish xarajati | B17: =B6*Tannarx!$C$12 -> 0 | C17: =C6*Tannarx!$C$12 -> 7682.2727 | D17: =D6*Tannarx!$C$12 -> 64018.939 | E17: =E6*Tannarx!$C$12 -> 140841.67 | F17: =F6*Tannarx!$C$12 -> 148523.94 | G17: =G6*Tannarx!$C$12 -> 148523.94 | H17: =H6*Tannarx!$C$12 -> 148523.94 | I17: =I6*Tannarx!$C$12 -> 148523.94
A18: Sotib olingan PHA | B18: =B10*Kirish!$B$31 -> 0 | C18: =C10*Kirish!$B$31 -> 0 | D18: =D10*Kirish!$B$31 -> 0 | E18: =E10*Kirish!$B$31 -> 0 | F18: =F10*Kirish!$B$31 -> 0 | G18: =G10*Kirish!$B$31 -> 0 | H18: =H10*Kirish!$B$31 -> 0 | I18: =I10*Kirish!$B$31 -> 0
A19: Sotish va logistika | B19: =B14*Kirish!$B$32 -> 0 | C19: =C14*Kirish!$B$32 -> 46800 | D19: =D14*Kirish!$B$32 -> 93780 | E19: =E14*Kirish!$B$32 -> 125340 | F19: =F14*Kirish!$B$32 -> 133095 | G19: =G14*Kirish!$B$32 -> 133095 | H19: =H14*Kirish!$B$32 -> 133095 | I19: =I14*Kirish!$B$32 -> 133095
A20: Jami o'zgaruvchan xarajat | B20: =SUM(B16:B19) -> 0 | C20: =SUM(C16:C19) -> 694453.07 | D20: =SUM(D16:D19) -> 1400847.7 | E20: =SUM(E16:E19) -> 1882588.1 | F20: =SUM(F16:F19) -> 1999050.7 | G20: =SUM(G16:G19) -> 1999050.7 | H20: =SUM(H16:H19) -> 1999050.7 | I20: =SUM(I16:I19) -> 1999050.7
A21: MARJINAL FOYDA | B21: =B14-B20 -> 0 | C21: =C14-C20 -> 475546.93 | D21: =D14-D20 -> 943652.26 | E21: =E14-E20 -> 1250911.9 | F21: =F14-F20 -> 1328324.3 | G21: =G14-G20 -> 1328324.3 | H21: =H14-H20 -> 1328324.3 | I21: =I14-I20 -> 1328324.3
A22: Doimiy xarajatlar
A23: Faoliyat koeffitsienti | B23: 0.5 | C23: 1 | D23: 1 | E23: 1 | F23: 1 | G23: 1 | H23: 1 | I23: 1 | J23: 0-yil: qurilish va ilmiy ish davri — xarajatlar 50%
A24: Ish haqi + ijtimoiy soliq | B24: =B23*IF(0<=1,Xodimlar!$E$16,Xodimlar!$F$16) -> 87024 | C24: =C23*IF(1<=1,Xodimlar!$E$16,Xodimlar!$F$16) -> 174048 | D24: =D23*IF(2<=1,Xodimlar!$E$16,Xodimlar!$F$16) -> 285600 | E24: =E23*IF(3<=1,Xodimlar!$E$16,Xodimlar!$F$16) -> 285600 | F24: =F23*IF(4<=1,Xodimlar!$E$16,Xodimlar!$F$16) -> 285600 | G24: =G23*IF(5<=1,Xodimlar!$E$16,Xodimlar!$F$16) -> 285600 | H24: =H23*IF(6<=1,Xodimlar!$E$16,Xodimlar!$F$16) -> 285600 | I24: =I23*IF(7<=1,Xodimlar!$E$16,Xodimlar!$F$16) -> 285600
A25: Ijara | B25: =Kirish!$B$34*Kirish!$B$35*12 -> 72000 | C25: =Kirish!$B$34*Kirish!$B$35*12 -> 72000 | D25: =Kirish!$B$34*Kirish!$B$35*12 -> 72000 | E25: =Kirish!$B$34*Kirish!$B$35*12 -> 72000 | F25: =Kirish!$B$34*Kirish!$B$35*12 -> 72000 | G25: =Kirish!$B$34*Kirish!$B$35*12 -> 72000 | H25: =Kirish!$B$34*Kirish!$B$35*12 -> 72000 | I25: =Kirish!$B$34*Kirish!$B$35*12 -> 72000
A26: Ta'mirlash | B26: =IF(0>=1,CAPEX!$F$42,0)*Kirish!$B$36+IF(0>=2,CAPEX!$G$42,0)*Kirish!$B$36 -> 0 | C26: =IF(1>=1,CAPEX!$F$42,0)*Kirish!$B$36+IF(1>=2,CAPEX!$G$42,0)*Kirish!$B$36 -> 12285 | D26: =IF(2>=1,CAPEX!$F$42,0)*Kirish!$B$36+IF(2>=2,CAPEX!$G$42,0)*Kirish!$B$36 -> 33285 | E26: =IF(3>=1,CAPEX!$F$42,0)*Kirish!$B$36+IF(3>=2,CAPEX!$G$42,0)*Kirish!$B$36 -> 33285 | F26: =IF(4>=1,CAPEX!$F$42,0)*Kirish!$B$36+IF(4>=2,CAPEX!$G$42,0)*Kirish!$B$36 -> 33285 | G26: =IF(5>=1,CAPEX!$F$42,0)*Kirish!$B$36+IF(5>=2,CAPEX!$G$42,0)*Kirish!$B$36 -> 33285 | H26: =IF(6>=1,CAPEX!$F$42,0)*Kirish!$B$36+IF(6>=2,CAPEX!$G$42,0)*Kirish!$B$36 -> 33285 | I26: =IF(7>=1,CAPEX!$F$42,0)*Kirish!$B$36+IF(7>=2,CAPEX!$G$42,0)*Kirish!$B$36 -> 33285
A27: Marketing, ma'muriy, sertifikat, ITI, kommunal | B27: =B23*(Kirish!$B$37+Kirish!$B$38+Kirish!$B$39+Kirish!$B$40+Kirish!$B$41) -> 48500 | C27: =C23*(Kirish!$B$37+Kirish!$B$38+Kirish!$B$39+Kirish!$B$40+Kirish!$B$41) -> 97000 | D27: =D23*(Kirish!$B$37+Kirish!$B$38+Kirish!$B$39+Kirish!$B$40+Kirish!$B$41) -> 97000 | E27: =E23*(Kirish!$B$37+Kirish!$B$38+Kirish!$B$39+Kirish!$B$40+Kirish!$B$41) -> 97000 | F27: =F23*(Kirish!$B$37+Kirish!$B$38+Kirish!$B$39+Kirish!$B$40+Kirish!$B$41) -> 97000 | G27: =G23*(Kirish!$B$37+Kirish!$B$38+Kirish!$B$39+Kirish!$B$40+Kirish!$B$41) -> 97000 | H27: =H23*(Kirish!$B$37+Kirish!$B$38+Kirish!$B$39+Kirish!$B$40+Kirish!$B$41) -> 97000 | I27: =I23*(Kirish!$B$37+Kirish!$B$38+Kirish!$B$39+Kirish!$B$40+Kirish!$B$41) -> 97000
A28: Jami doimiy xarajat | B28: =SUM(B24:B27) -> 207524 | C28: =SUM(C24:C27) -> 355333 | D28: =SUM(D24:D27) -> 487885 | E28: =SUM(E24:E27) -> 487885 | F28: =SUM(F24:F27) -> 487885 | G28: =SUM(G24:G27) -> 487885 | H28: =SUM(H24:H27) -> 487885 | I28: =SUM(I24:I27) -> 487885
A29: Foyda
A30: EBITDA | B30: =B21-B28 -> -207524 | C30: =C21-C28 -> 120213.93 | D30: =D21-D28 -> 455767.26 | E30: =E21-E28 -> 763026.93 | F30: =F21-F28 -> 840439.26 | G30: =G21-G28 -> 840439.26 | H30: =H21-H28 -> 840439.26 | I30: =I21-I28 -> 840439.26
A31: EBITDA rentabelligi | B31: =IF(B14=0,0,B30/B14) -> 0 | C31: =IF(C14=0,0,C30/C14) -> 0.10274695 | D31: =IF(D14=0,0,D30/D14) -> 0.19439849 | E31: =IF(E14=0,0,E30/E14) -> 0.24350628 | F31: =IF(F14=0,0,F30/F14) -> 0.25258327 | G31: =IF(G14=0,0,G30/G14) -> 0.25258327 | H31: =IF(H14=0,0,H30/H14) -> 0.25258327 | I31: =IF(I14=0,0,I30/I14) -> 0.25258327
A32: Amortizatsiya | B32: =IF(0>=1,CAPEX!$F$48,0)/Kirish!$B$43+IF(0>=2,CAPEX!$G$48,0)/Kirish!$B$43 -> 0 | C32: =IF(1>=1,CAPEX!$F$48,0)/Kirish!$B$43+IF(1>=2,CAPEX!$G$48,0)/Kirish!$B$43 -> 72607.15 | D32: =IF(2>=1,CAPEX!$F$48,0)/Kirish!$B$43+IF(2>=2,CAPEX!$G$48,0)/Kirish!$B$43 -> 170397.15 | E32: =IF(3>=1,CAPEX!$F$48,0)/Kirish!$B$43+IF(3>=2,CAPEX!$G$48,0)/Kirish!$B$43 -> 170397.15 | F32: =IF(4>=1,CAPEX!$F$48,0)/Kirish!$B$43+IF(4>=2,CAPEX!$G$48,0)/Kirish!$B$43 -> 170397.15 | G32: =IF(5>=1,CAPEX!$F$48,0)/Kirish!$B$43+IF(5>=2,CAPEX!$G$48,0)/Kirish!$B$43 -> 170397.15 | H32: =IF(6>=1,CAPEX!$F$48,0)/Kirish!$B$43+IF(6>=2,CAPEX!$G$48,0)/Kirish!$B$43 -> 170397.15 | I32: =IF(7>=1,CAPEX!$F$48,0)/Kirish!$B$43+IF(7>=2,CAPEX!$G$48,0)/Kirish!$B$43 -> 170397.15
A33: Foiz va soliqqacha foyda (EBIT) | B33: =B30-B32 -> -207524 | C33: =C30-C32 -> 47606.777 | D33: =D30-D32 -> 285370.11 | E33: =E30-E32 -> 592629.78 | F33: =F30-F32 -> 670042.11 | G33: =G30-G32 -> 670042.11 | H33: =H30-H32 -> 670042.11 | I33: =I30-I32 -> 670042.11
A34: Kredit foizi | B34: =(0+B48)/2*Kirish!$B$46 -> 18151.787 | C34: =(B48+C48)/2*Kirish!$B$46 -> 60751.075 | D34: =(C48+D48)/2*Kirish!$B$46 -> 76678.717 | E34: =(D48+E48)/2*Kirish!$B$46 -> 59639.003 | F34: =(E48+F48)/2*Kirish!$B$46 -> 42599.287 | G34: =(F48+G48)/2*Kirish!$B$46 -> 25559.572 | H34: =(G48+H48)/2*Kirish!$B$46 -> 8519.8575 | I34: =(H48+I48)/2*Kirish!$B$46 -> 0
A35: Soliqqacha foyda | B35: =B33-B34 -> -225675.79 | C35: =C33-C34 -> -13144.298 | D35: =D33-D34 -> 208691.39 | E35: =E33-E34 -> 532990.78 | F35: =F33-F34 -> 627442.82 | G35: =G33-G34 -> 644482.54 | H35: =H33-H34 -> 661522.25 | I35: =I33-I34 -> 670042.11
A36: Foyda solig'i | B36: =MAX(0,B35)*Kirish!$B$8 -> 0 | C36: =MAX(0,C35)*Kirish!$B$8 -> 0 | D36: =MAX(0,D35)*Kirish!$B$8 -> 31303.709 | E36: =MAX(0,E35)*Kirish!$B$8 -> 79948.617 | F36: =MAX(0,F35)*Kirish!$B$8 -> 94116.423 | G36: =MAX(0,G35)*Kirish!$B$8 -> 96672.381 | H36: =MAX(0,H35)*Kirish!$B$8 -> 99228.338 | I36: =MAX(0,I35)*Kirish!$B$8 -> 100506.32 | J36: Soddalashtirish: zarar keyingi yillarga o'tkazilmaydi (konservativ)
A37: SOF FOYDA | B37: =B35-B36 -> -225675.79 | C37: =C35-C36 -> -13144.298 | D37: =D35-D36 -> 177387.68 | E37: =E35-E36 -> 453042.16 | F37: =F35-F36 -> 533326.4 | G37: =G35-G36 -> 547810.16 | H37: =H35-H36 -> 562293.92 | I37: =I35-I36 -> 569535.79
A38: Loyiha pul oqimi (moliyalashtirishsiz)
A39: Kapital xarajatlar | B39: =-(CAPEX!$F$48+0) -> -726071.5 | C39: =-(0+CAPEX!$G$48) -> -977900 | D39: =-(0+0) -> 0 | E39: =-(0+0) -> 0 | F39: =-(0+0) -> 0 | G39: =-(0+0) -> 0 | H39: =-(0+0) -> 0 | I39: =-(0+0) -> 0
A40: Aylanma kapital o'zgarishi | B40: =-B14*Kirish!$B$44 -> 0 | C40: =-(C14-B14)*Kirish!$B$44 -> -175500 | D40: =-(D14-C14)*Kirish!$B$44 -> -176175 | E40: =-(E14-D14)*Kirish!$B$44 -> -118350 | F40: =-(F14-E14)*Kirish!$B$44 -> -29081.25 | G40: =-(G14-F14)*Kirish!$B$44 -> 0 | H40: =-(H14-G14)*Kirish!$B$44 -> 0 | I40: =-(I14-H14)*Kirish!$B$44 -> 0
A41: Soliq (moliyalashtirishsiz) | B41: =-MAX(0,B33)*Kirish!$B$8 -> 0 | C41: =-MAX(0,C33)*Kirish!$B$8 -> -7141.0166 | D41: =-MAX(0,D33)*Kirish!$B$8 -> -42805.517 | E41: =-MAX(0,E33)*Kirish!$B$8 -> -88894.467 | F41: =-MAX(0,F33)*Kirish!$B$8 -> -100506.32 | G41: =-MAX(0,G33)*Kirish!$B$8 -> -100506.32 | H41: =-MAX(0,H33)*Kirish!$B$8 -> -100506.32 | I41: =-MAX(0,I33)*Kirish!$B$8 -> -100506.32
...

Sheet Sezgirlik
A1: Sezgirlik tahlili — 4-yil (2031) EBITDA, $
A2: Satrlar: paket narxi o'zgarishi; ustunlar: PBAT narxi o'zgarishi. Boshqa barcha omillar o'zgarmas.
A4: Paket narxi \ PBAT narxi | B4: -0.2 | C4: -0.1 | D4: 0 | E4: 0.1 | F4: 0.2
A5: -0.2 | B5: =Prognoz!$F$30+$A5*Prognoz!$F$5*Kirish!$B$30*(1-Kirish!$B$32)-B$4*Prognoz!$F$5*(1-Prognoz!$F$7-Kirish!$B$24)*Kirish!$B$25*Kirish!$B$21*(1+Kirish!$B$26) -> 390763.08 | C5: =Prognoz!$F$30+$A5*Prognoz!$F$5*Kirish!$B$30*(1-Kirish!$B$32)-C$4*Prognoz!$F$5*(1-Prognoz!$F$7-Kirish!$B$24)*Kirish!$B$25*Kirish!$B$21*(1+Kirish!$B$26) -> 297361.17 | D5: =Prognoz!$F$30+$A5*Prognoz!$F$5*Kirish!$B$30*(1-Kirish!$B$32)-D$4*Prognoz!$F$5*(1-Prognoz!$F$7-Kirish!$B$24)*Kirish!$B$25*Kirish!$B$21*(1+Kirish!$B$26) -> 203959.26 | E5: =Prognoz!$F$30+$A5*Prognoz!$F$5*Kirish!$B$30*(1-Kirish!$B$32)-E$4*Prognoz!$F$5*(1-Prognoz!$F$7-Kirish!$B$24)*Kirish!$B$25*Kirish!$B$21*(1+Kirish!$B$26) -> 110557.35 | F5: =Prognoz!$F$30+$A5*Prognoz!$F$5*Kirish!$B$30*(1-Kirish!$B$32)-F$4*Prognoz!$F$5*(1-Prognoz!$F$7-Kirish!$B$24)*Kirish!$B$25*Kirish!$B$21*(1+Kirish!$B$26) -> 17155.441
A6: -0.1 | B6: =Prognoz!$F$30+$A6*Prognoz!$F$5*Kirish!$B$30*(1-Kirish!$B$32)-B$4*Prognoz!$F$5*(1-Prognoz!$F$7-Kirish!$B$24)*Kirish!$B$25*Kirish!$B$21*(1+Kirish!$B$26) -> 709003.08 | C6: =Prognoz!$F$30+$A6*Prognoz!$F$5*Kirish!$B$30*(1-Kirish!$B$32)-C$4*Prognoz!$F$5*(1-Prognoz!$F$7-Kirish!$B$24)*Kirish!$B$25*Kirish!$B$21*(1+Kirish!$B$26) -> 615601.17 | D6: =Prognoz!$F$30+$A6*Prognoz!$F$5*Kirish!$B$30*(1-Kirish!$B$32)-D$4*Prognoz!$F$5*(1-Prognoz!$F$7-Kirish!$B$24)*Kirish!$B$25*Kirish!$B$21*(1+Kirish!$B$26) -> 522199.26 | E6: =Prognoz!$F$30+$A6*Prognoz!$F$5*Kirish!$B$30*(1-Kirish!$B$32)-E$4*Prognoz!$F$5*(1-Prognoz!$F$7-Kirish!$B$24)*Kirish!$B$25*Kirish!$B$21*(1+Kirish!$B$26) -> 428797.35 | F6: =Prognoz!$F$30+$A6*Prognoz!$F$5*Kirish!$B$30*(1-Kirish!$B$32)-F$4*Prognoz!$F$5*(1-Prognoz!$F$7-Kirish!$B$24)*Kirish!$B$25*Kirish!$B$21*(1+Kirish!$B$26) -> 335395.44
A7: 0 | B7: =Prognoz!$F$30+$A7*Prognoz!$F$5*Kirish!$B$30*(1-Kirish!$B$32)-B$4*Prognoz!$F$5*(1-Prognoz!$F$7-Kirish!$B$24)*Kirish!$B$25*Kirish!$B$21*(1+Kirish!$B$26) -> 1027243.1 | C7: =Prognoz!$F$30+$A7*Prognoz!$F$5*Kirish!$B$30*(1-Kirish!$B$32)-C$4*Prognoz!$F$5*(1-Prognoz!$F$7-Kirish!$B$24)*Kirish!$B$25*Kirish!$B$21*(1+Kirish!$B$26) -> 933841.17 | D7: =Prognoz!$F$30+$A7*Prognoz!$F$5*Kirish!$B$30*(1-Kirish!$B$32)-D$4*Prognoz!$F$5*(1-Prognoz!$F$7-Kirish!$B$24)*Kirish!$B$25*Kirish!$B$21*(1+Kirish!$B$26) -> 840439.26 | E7: =Prognoz!$F$30+$A7*Prognoz!$F$5*Kirish!$B$30*(1-Kirish!$B$32)-E$4*Prognoz!$F$5*(1-Prognoz!$F$7-Kirish!$B$24)*Kirish!$B$25*Kirish!$B$21*(1+Kirish!$B$26) -> 747037.35 | F7: =Prognoz!$F$30+$A7*Prognoz!$F$5*Kirish!$B$30*(1-Kirish!$B$32)-F$4*Prognoz!$F$5*(1-Prognoz!$F$7-Kirish!$B$24)*Kirish!$B$25*Kirish!$B$21*(1+Kirish!$B$26) -> 653635.44
A8: 0.1 | B8: =Prognoz!$F$30+$A8*Prognoz!$F$5*Kirish!$B$30*(1-Kirish!$B$32)-B$4*Prognoz!$F$5*(1-Prognoz!$F$7-Kirish!$B$24)*Kirish!$B$25*Kirish!$B$21*(1+Kirish!$B$26) -> 1345483.1 | C8: =Prognoz!$F$30+$A8*Prognoz!$F$5*Kirish!$B$30*(1-Kirish!$B$32)-C$4*Prognoz!$F$5*(1-Prognoz!$F$7-Kirish!$B$24)*Kirish!$B$25*Kirish!$B$21*(1+Kirish!$B$26) -> 1252081.2 | D8: =Prognoz!$F$30+$A8*Prognoz!$F$5*Kirish!$B$30*(1-Kirish!$B$32)-D$4*Prognoz!$F$5*(1-Prognoz!$F$7-Kirish!$B$24)*Kirish!$B$25*Kirish!$B$21*(1+Kirish!$B$26) -> 1158679.3 | E8: =Prognoz!$F$30+$A8*Prognoz!$F$5*Kirish!$B$30*(1-Kirish!$B$32)-E$4*Prognoz!$F$5*(1-Prognoz!$F$7-Kirish!$B$24)*Kirish!$B$25*Kirish!$B$21*(1+Kirish!$B$26) -> 1065277.4 | F8: =Prognoz!$F$30+$A8*Prognoz!$F$5*Kirish!$B$30*(1-Kirish!$B$32)-F$4*Prognoz!$F$5*(1-Prognoz!$F$7-Kirish!$B$24)*Kirish!$B$25*Kirish!$B$21*(1+Kirish!$B$26) -> 971875.44
A9: 0.2 | B9: =Prognoz!$F$30+$A9*Prognoz!$F$5*Kirish!$B$30*(1-Kirish!$B$32)-B$4*Prognoz!$F$5*(1-Prognoz!$F$7-Kirish!$B$24)*Kirish!$B$25*Kirish!$B$21*(1+Kirish!$B$26) -> 1663723.1 | C9: =Prognoz!$F$30+$A9*Prognoz!$F$5*Kirish!$B$30*(1-Kirish!$B$32)-C$4*Prognoz!$F$5*(1-Prognoz!$F$7-Kirish!$B$24)*Kirish!$B$25*Kirish!$B$21*(1+Kirish!$B$26) -> 1570321.2 | D9: =Prognoz!$F$30+$A9*Prognoz!$F$5*Kirish!$B$30*(1-Kirish!$B$32)-D$4*Prognoz!$F$5*(1-Prognoz!$F$7-Kirish!$B$24)*Kirish!$B$25*Kirish!$B$21*(1+Kirish!$B$26) -> 1476919.3 | E9: =Prognoz!$F$30+$A9*Prognoz!$F$5*Kirish!$B$30*(1-Kirish!$B$32)-E$4*Prognoz!$F$5*(1-Prognoz!$F$7-Kirish!$B$24)*Kirish!$B$25*Kirish!$B$21*(1+Kirish!$B$26) -> 1383517.4 | F9: =Prognoz!$F$30+$A9*Prognoz!$F$5*Kirish!$B$30*(1-Kirish!$B$32)-F$4*Prognoz!$F$5*(1-Prognoz!$F$7-Kirish!$B$24)*Kirish!$B$25*Kirish!$B$21*(1+Kirish!$B$26) -> 1290115.4
A11: Asosiy xulosa: rentabellik eng ko'p sotish narxiga, keyin PBAT narxiga bog'liq.

Sheet Eski vs Yangi
A1: Dastlabki taqdimotdagi raqamlar va tuzatilgan qiymatlar
A3: Ko'rsatkich | B3: Dastlabki taqdimot | C3: Tuzatilgan (model) | D3: Nima uchun o'zgardi
A4: 1 t plastik sotish narxi | B4: 250 | C4: =Kirish!$B$30 -> 3900 | D4: 250 $/t polietilendan (≈1 200 $/t) ham 5 baravar arzon. PHA bozor narxi 3 400–3 700 $/t (IMARC, 2025), kompost bo'ladigan paket ≈3 900 $/t.
A5: 1 t tannarx | B5: 95 | C5: =Tannarx!C22 -> 2195.2797 | D5: Faqat yog' xomashyosining o'zi ≈900 $/t PHA (1,8 t yog' kerak). Elektr, gaz, kimyoviy moddalar, PBAT/PLA qo'shilgan.
A6: 1 t xomashyo xarajati | B6: 50 | C6: =Tannarx!C5 -> 909.09091 | D6: 1 t PHA uchun ~1,8 t uglerod manbai kerak; 50 $ jismonan mumkin emas.
A7: Oylik ishlab chiqarish (t, barqaror yil) | B7: 50 | C7: =Prognoz!F5/12 -> 70.833333 | D7: 25 000 $ lik uskuna bilan oyiga 50 t PHA olish mumkin emas (≈ 600 m³ fermenter kerak). Yangi model: oyiga ~71 t tayyor paket/plyonka va ~4,8 t PHA.
A8: Jami boshlang'ich investitsiya ($) | B8: 60000 | C8: =CAPEX!$H$48 -> 1703971.5 | D8: Real narxlar: 10 m³ fermenter ≈ 50–90 ming $, separator ≈ 70 ming $, ekstruder ≈ 85 ming $.
A9: Yillik foyda ($) | B9: 93000 | C9: =Prognoz!F37 -> 533326.4 | D9: Barqaror yil (2031) sof foydasi, soliq va kredit foizi bilan.
A10: Investitsiya qaytimi | B10: 8 oy | C10: =Prognoz!B62 -> 4.6358707 | D10: Kimyo-biotexnologiya korxonasi uchun 4–6 yil — sanoat uchun odatiy.
